{
 "cells": [
  {
   "cell_type": "code",
   "execution_count": 23,
   "id": "32d2eaa0-209b-470c-b6ea-b97201461e9b",
   "metadata": {},
   "outputs": [],
   "source": [
    "customer = {\n",
    "    \"gender\": \"female\",\n",
    "    \"seniorcitizen\": 0,\n",
    "    \"partner\": \"yes\",\n",
    "    \"dependents\": \"no\",\n",
    "    \"phoneservice\": \"no\",\n",
    "    \"multiplelines\": \"no_phone_service\",\n",
    "    \"internetservice\": \"dsl\",\n",
    "    \"onlinesecurity\": \"no\",\n",
    "    \"onlinebackup\": \"yes\",\n",
    "    \"deviceprotection\": \"no\",\n",
    "    \"techsupport\": \"no\",\n",
    "    \"streamingtv\": \"no\",\n",
    "    \"streamingmovies\": \"no\",\n",
    "    \"contract\": \"month-to-month\",\n",
    "    \"paperlessbilling\": \"yes\",\n",
    "    \"paymentmethod\": \"electronic_check\",\n",
    "    \"tenure\": 1,\n",
    "    \"monthlycharges\": 29.85,\n",
    "    \"totalcharges\": 29.85\n",
    "}"
   ]
  },
  {
   "cell_type": "code",
   "execution_count": 24,
   "id": "f08a96ec-a117-4297-a4f7-7ecaba305e08",
   "metadata": {},
   "outputs": [],
   "source": [
    "import requests ## to use the POST method we use a library named requests"
   ]
  },
  {
   "cell_type": "code",
   "execution_count": 25,
   "id": "82762a39-10a8-493e-a841-41b6c63063c9",
   "metadata": {},
   "outputs": [],
   "source": [
    "url = 'http://localhost:9696/predict' ## this is the route we made for prediction"
   ]
  },
  {
   "cell_type": "code",
   "execution_count": 29,
   "id": "7bdc9d55-eef5-4168-8f3d-d5b907103f84",
   "metadata": {},
   "outputs": [
    {
     "ename": "ConnectionError",
     "evalue": "HTTPConnectionPool(host='localhost', port=9696): Max retries exceeded with url: /predict (Caused by NewConnectionError('<urllib3.connection.HTTPConnection object at 0x7bc00c08f4a0>: Failed to establish a new connection: [Errno 111] Connection refused'))",
     "output_type": "error",
     "traceback": [
      "\u001b[31m---------------------------------------------------------------------------\u001b[39m",
      "\u001b[31mConnectionRefusedError\u001b[39m                    Traceback (most recent call last)",
      "\u001b[36mFile \u001b[39m\u001b[32m~/.local/lib/python3.12/site-packages/urllib3/connection.py:198\u001b[39m, in \u001b[36mHTTPConnection._new_conn\u001b[39m\u001b[34m(self)\u001b[39m\n\u001b[32m    197\u001b[39m \u001b[38;5;28;01mtry\u001b[39;00m:\n\u001b[32m--> \u001b[39m\u001b[32m198\u001b[39m     sock = \u001b[43mconnection\u001b[49m\u001b[43m.\u001b[49m\u001b[43mcreate_connection\u001b[49m\u001b[43m(\u001b[49m\n\u001b[32m    199\u001b[39m \u001b[43m        \u001b[49m\u001b[43m(\u001b[49m\u001b[38;5;28;43mself\u001b[39;49m\u001b[43m.\u001b[49m\u001b[43m_dns_host\u001b[49m\u001b[43m,\u001b[49m\u001b[43m \u001b[49m\u001b[38;5;28;43mself\u001b[39;49m\u001b[43m.\u001b[49m\u001b[43mport\u001b[49m\u001b[43m)\u001b[49m\u001b[43m,\u001b[49m\n\u001b[32m    200\u001b[39m \u001b[43m        \u001b[49m\u001b[38;5;28;43mself\u001b[39;49m\u001b[43m.\u001b[49m\u001b[43mtimeout\u001b[49m\u001b[43m,\u001b[49m\n\u001b[32m    201\u001b[39m \u001b[43m        \u001b[49m\u001b[43msource_address\u001b[49m\u001b[43m=\u001b[49m\u001b[38;5;28;43mself\u001b[39;49m\u001b[43m.\u001b[49m\u001b[43msource_address\u001b[49m\u001b[43m,\u001b[49m\n\u001b[32m    202\u001b[39m \u001b[43m        \u001b[49m\u001b[43msocket_options\u001b[49m\u001b[43m=\u001b[49m\u001b[38;5;28;43mself\u001b[39;49m\u001b[43m.\u001b[49m\u001b[43msocket_options\u001b[49m\u001b[43m,\u001b[49m\n\u001b[32m    203\u001b[39m \u001b[43m    \u001b[49m\u001b[43m)\u001b[49m\n\u001b[32m    204\u001b[39m \u001b[38;5;28;01mexcept\u001b[39;00m socket.gaierror \u001b[38;5;28;01mas\u001b[39;00m e:\n",
      "\u001b[36mFile \u001b[39m\u001b[32m~/.local/lib/python3.12/site-packages/urllib3/util/connection.py:85\u001b[39m, in \u001b[36mcreate_connection\u001b[39m\u001b[34m(address, timeout, source_address, socket_options)\u001b[39m\n\u001b[32m     84\u001b[39m \u001b[38;5;28;01mtry\u001b[39;00m:\n\u001b[32m---> \u001b[39m\u001b[32m85\u001b[39m     \u001b[38;5;28;01mraise\u001b[39;00m err\n\u001b[32m     86\u001b[39m \u001b[38;5;28;01mfinally\u001b[39;00m:\n\u001b[32m     87\u001b[39m     \u001b[38;5;66;03m# Break explicitly a reference cycle\u001b[39;00m\n",
      "\u001b[36mFile \u001b[39m\u001b[32m~/.local/lib/python3.12/site-packages/urllib3/util/connection.py:73\u001b[39m, in \u001b[36mcreate_connection\u001b[39m\u001b[34m(address, timeout, source_address, socket_options)\u001b[39m\n\u001b[32m     72\u001b[39m     sock.bind(source_address)\n\u001b[32m---> \u001b[39m\u001b[32m73\u001b[39m \u001b[43msock\u001b[49m\u001b[43m.\u001b[49m\u001b[43mconnect\u001b[49m\u001b[43m(\u001b[49m\u001b[43msa\u001b[49m\u001b[43m)\u001b[49m\n\u001b[32m     74\u001b[39m \u001b[38;5;66;03m# Break explicitly a reference cycle\u001b[39;00m\n",
      "\u001b[31mConnectionRefusedError\u001b[39m: [Errno 111] Connection refused",
      "\nThe above exception was the direct cause of the following exception:\n",
      "\u001b[31mNewConnectionError\u001b[39m                        Traceback (most recent call last)",
      "\u001b[36mFile \u001b[39m\u001b[32m~/.local/lib/python3.12/site-packages/urllib3/connectionpool.py:787\u001b[39m, in \u001b[36mHTTPConnectionPool.urlopen\u001b[39m\u001b[34m(self, method, url, body, headers, retries, redirect, assert_same_host, timeout, pool_timeout, release_conn, chunked, body_pos, preload_content, decode_content, **response_kw)\u001b[39m\n\u001b[32m    786\u001b[39m \u001b[38;5;66;03m# Make the request on the HTTPConnection object\u001b[39;00m\n\u001b[32m--> \u001b[39m\u001b[32m787\u001b[39m response = \u001b[38;5;28;43mself\u001b[39;49m\u001b[43m.\u001b[49m\u001b[43m_make_request\u001b[49m\u001b[43m(\u001b[49m\n\u001b[32m    788\u001b[39m \u001b[43m    \u001b[49m\u001b[43mconn\u001b[49m\u001b[43m,\u001b[49m\n\u001b[32m    789\u001b[39m \u001b[43m    \u001b[49m\u001b[43mmethod\u001b[49m\u001b[43m,\u001b[49m\n\u001b[32m    790\u001b[39m \u001b[43m    \u001b[49m\u001b[43murl\u001b[49m\u001b[43m,\u001b[49m\n\u001b[32m    791\u001b[39m \u001b[43m    \u001b[49m\u001b[43mtimeout\u001b[49m\u001b[43m=\u001b[49m\u001b[43mtimeout_obj\u001b[49m\u001b[43m,\u001b[49m\n\u001b[32m    792\u001b[39m \u001b[43m    \u001b[49m\u001b[43mbody\u001b[49m\u001b[43m=\u001b[49m\u001b[43mbody\u001b[49m\u001b[43m,\u001b[49m\n\u001b[32m    793\u001b[39m \u001b[43m    \u001b[49m\u001b[43mheaders\u001b[49m\u001b[43m=\u001b[49m\u001b[43mheaders\u001b[49m\u001b[43m,\u001b[49m\n\u001b[32m    794\u001b[39m \u001b[43m    \u001b[49m\u001b[43mchunked\u001b[49m\u001b[43m=\u001b[49m\u001b[43mchunked\u001b[49m\u001b[43m,\u001b[49m\n\u001b[32m    795\u001b[39m \u001b[43m    \u001b[49m\u001b[43mretries\u001b[49m\u001b[43m=\u001b[49m\u001b[43mretries\u001b[49m\u001b[43m,\u001b[49m\n\u001b[32m    796\u001b[39m \u001b[43m    \u001b[49m\u001b[43mresponse_conn\u001b[49m\u001b[43m=\u001b[49m\u001b[43mresponse_conn\u001b[49m\u001b[43m,\u001b[49m\n\u001b[32m    797\u001b[39m \u001b[43m    \u001b[49m\u001b[43mpreload_content\u001b[49m\u001b[43m=\u001b[49m\u001b[43mpreload_content\u001b[49m\u001b[43m,\u001b[49m\n\u001b[32m    798\u001b[39m \u001b[43m    \u001b[49m\u001b[43mdecode_content\u001b[49m\u001b[43m=\u001b[49m\u001b[43mdecode_content\u001b[49m\u001b[43m,\u001b[49m\n\u001b[32m    799\u001b[39m \u001b[43m    \u001b[49m\u001b[43m*\u001b[49m\u001b[43m*\u001b[49m\u001b[43mresponse_kw\u001b[49m\u001b[43m,\u001b[49m\n\u001b[32m    800\u001b[39m \u001b[43m\u001b[49m\u001b[43m)\u001b[49m\n\u001b[32m    802\u001b[39m \u001b[38;5;66;03m# Everything went great!\u001b[39;00m\n",
      "\u001b[36mFile \u001b[39m\u001b[32m~/.local/lib/python3.12/site-packages/urllib3/connectionpool.py:493\u001b[39m, in \u001b[36mHTTPConnectionPool._make_request\u001b[39m\u001b[34m(self, conn, method, url, body, headers, retries, timeout, chunked, response_conn, preload_content, decode_content, enforce_content_length)\u001b[39m\n\u001b[32m    492\u001b[39m \u001b[38;5;28;01mtry\u001b[39;00m:\n\u001b[32m--> \u001b[39m\u001b[32m493\u001b[39m     \u001b[43mconn\u001b[49m\u001b[43m.\u001b[49m\u001b[43mrequest\u001b[49m\u001b[43m(\u001b[49m\n\u001b[32m    494\u001b[39m \u001b[43m        \u001b[49m\u001b[43mmethod\u001b[49m\u001b[43m,\u001b[49m\n\u001b[32m    495\u001b[39m \u001b[43m        \u001b[49m\u001b[43murl\u001b[49m\u001b[43m,\u001b[49m\n\u001b[32m    496\u001b[39m \u001b[43m        \u001b[49m\u001b[43mbody\u001b[49m\u001b[43m=\u001b[49m\u001b[43mbody\u001b[49m\u001b[43m,\u001b[49m\n\u001b[32m    497\u001b[39m \u001b[43m        \u001b[49m\u001b[43mheaders\u001b[49m\u001b[43m=\u001b[49m\u001b[43mheaders\u001b[49m\u001b[43m,\u001b[49m\n\u001b[32m    498\u001b[39m \u001b[43m        \u001b[49m\u001b[43mchunked\u001b[49m\u001b[43m=\u001b[49m\u001b[43mchunked\u001b[49m\u001b[43m,\u001b[49m\n\u001b[32m    499\u001b[39m \u001b[43m        \u001b[49m\u001b[43mpreload_content\u001b[49m\u001b[43m=\u001b[49m\u001b[43mpreload_content\u001b[49m\u001b[43m,\u001b[49m\n\u001b[32m    500\u001b[39m \u001b[43m        \u001b[49m\u001b[43mdecode_content\u001b[49m\u001b[43m=\u001b[49m\u001b[43mdecode_content\u001b[49m\u001b[43m,\u001b[49m\n\u001b[32m    501\u001b[39m \u001b[43m        \u001b[49m\u001b[43menforce_content_length\u001b[49m\u001b[43m=\u001b[49m\u001b[43menforce_content_length\u001b[49m\u001b[43m,\u001b[49m\n\u001b[32m    502\u001b[39m \u001b[43m    \u001b[49m\u001b[43m)\u001b[49m\n\u001b[32m    504\u001b[39m \u001b[38;5;66;03m# We are swallowing BrokenPipeError (errno.EPIPE) since the server is\u001b[39;00m\n\u001b[32m    505\u001b[39m \u001b[38;5;66;03m# legitimately able to close the connection after sending a valid response.\u001b[39;00m\n\u001b[32m    506\u001b[39m \u001b[38;5;66;03m# With this behaviour, the received response is still readable.\u001b[39;00m\n",
      "\u001b[36mFile \u001b[39m\u001b[32m~/.local/lib/python3.12/site-packages/urllib3/connection.py:494\u001b[39m, in \u001b[36mHTTPConnection.request\u001b[39m\u001b[34m(self, method, url, body, headers, chunked, preload_content, decode_content, enforce_content_length)\u001b[39m\n\u001b[32m    493\u001b[39m     \u001b[38;5;28mself\u001b[39m.putheader(header, value)\n\u001b[32m--> \u001b[39m\u001b[32m494\u001b[39m \u001b[38;5;28;43mself\u001b[39;49m\u001b[43m.\u001b[49m\u001b[43mendheaders\u001b[49m\u001b[43m(\u001b[49m\u001b[43m)\u001b[49m\n\u001b[32m    496\u001b[39m \u001b[38;5;66;03m# If we're given a body we start sending that in chunks.\u001b[39;00m\n",
      "\u001b[36mFile \u001b[39m\u001b[32m/opt/conda/lib/python3.12/http/client.py:1331\u001b[39m, in \u001b[36mHTTPConnection.endheaders\u001b[39m\u001b[34m(self, message_body, encode_chunked)\u001b[39m\n\u001b[32m   1330\u001b[39m     \u001b[38;5;28;01mraise\u001b[39;00m CannotSendHeader()\n\u001b[32m-> \u001b[39m\u001b[32m1331\u001b[39m \u001b[38;5;28;43mself\u001b[39;49m\u001b[43m.\u001b[49m\u001b[43m_send_output\u001b[49m\u001b[43m(\u001b[49m\u001b[43mmessage_body\u001b[49m\u001b[43m,\u001b[49m\u001b[43m \u001b[49m\u001b[43mencode_chunked\u001b[49m\u001b[43m=\u001b[49m\u001b[43mencode_chunked\u001b[49m\u001b[43m)\u001b[49m\n",
      "\u001b[36mFile \u001b[39m\u001b[32m/opt/conda/lib/python3.12/http/client.py:1091\u001b[39m, in \u001b[36mHTTPConnection._send_output\u001b[39m\u001b[34m(self, message_body, encode_chunked)\u001b[39m\n\u001b[32m   1090\u001b[39m \u001b[38;5;28;01mdel\u001b[39;00m \u001b[38;5;28mself\u001b[39m._buffer[:]\n\u001b[32m-> \u001b[39m\u001b[32m1091\u001b[39m \u001b[38;5;28;43mself\u001b[39;49m\u001b[43m.\u001b[49m\u001b[43msend\u001b[49m\u001b[43m(\u001b[49m\u001b[43mmsg\u001b[49m\u001b[43m)\u001b[49m\n\u001b[32m   1093\u001b[39m \u001b[38;5;28;01mif\u001b[39;00m message_body \u001b[38;5;129;01mis\u001b[39;00m \u001b[38;5;129;01mnot\u001b[39;00m \u001b[38;5;28;01mNone\u001b[39;00m:\n\u001b[32m   1094\u001b[39m \n\u001b[32m   1095\u001b[39m     \u001b[38;5;66;03m# create a consistent interface to message_body\u001b[39;00m\n",
      "\u001b[36mFile \u001b[39m\u001b[32m/opt/conda/lib/python3.12/http/client.py:1035\u001b[39m, in \u001b[36mHTTPConnection.send\u001b[39m\u001b[34m(self, data)\u001b[39m\n\u001b[32m   1034\u001b[39m \u001b[38;5;28;01mif\u001b[39;00m \u001b[38;5;28mself\u001b[39m.auto_open:\n\u001b[32m-> \u001b[39m\u001b[32m1035\u001b[39m     \u001b[38;5;28;43mself\u001b[39;49m\u001b[43m.\u001b[49m\u001b[43mconnect\u001b[49m\u001b[43m(\u001b[49m\u001b[43m)\u001b[49m\n\u001b[32m   1036\u001b[39m \u001b[38;5;28;01melse\u001b[39;00m:\n",
      "\u001b[36mFile \u001b[39m\u001b[32m~/.local/lib/python3.12/site-packages/urllib3/connection.py:325\u001b[39m, in \u001b[36mHTTPConnection.connect\u001b[39m\u001b[34m(self)\u001b[39m\n\u001b[32m    324\u001b[39m \u001b[38;5;28;01mdef\u001b[39;00m\u001b[38;5;250m \u001b[39m\u001b[34mconnect\u001b[39m(\u001b[38;5;28mself\u001b[39m) -> \u001b[38;5;28;01mNone\u001b[39;00m:\n\u001b[32m--> \u001b[39m\u001b[32m325\u001b[39m     \u001b[38;5;28mself\u001b[39m.sock = \u001b[38;5;28;43mself\u001b[39;49m\u001b[43m.\u001b[49m\u001b[43m_new_conn\u001b[49m\u001b[43m(\u001b[49m\u001b[43m)\u001b[49m\n\u001b[32m    326\u001b[39m     \u001b[38;5;28;01mif\u001b[39;00m \u001b[38;5;28mself\u001b[39m._tunnel_host:\n\u001b[32m    327\u001b[39m         \u001b[38;5;66;03m# If we're tunneling it means we're connected to our proxy.\u001b[39;00m\n",
      "\u001b[36mFile \u001b[39m\u001b[32m~/.local/lib/python3.12/site-packages/urllib3/connection.py:213\u001b[39m, in \u001b[36mHTTPConnection._new_conn\u001b[39m\u001b[34m(self)\u001b[39m\n\u001b[32m    212\u001b[39m \u001b[38;5;28;01mexcept\u001b[39;00m \u001b[38;5;167;01mOSError\u001b[39;00m \u001b[38;5;28;01mas\u001b[39;00m e:\n\u001b[32m--> \u001b[39m\u001b[32m213\u001b[39m     \u001b[38;5;28;01mraise\u001b[39;00m NewConnectionError(\n\u001b[32m    214\u001b[39m         \u001b[38;5;28mself\u001b[39m, \u001b[33mf\u001b[39m\u001b[33m\"\u001b[39m\u001b[33mFailed to establish a new connection: \u001b[39m\u001b[38;5;132;01m{\u001b[39;00me\u001b[38;5;132;01m}\u001b[39;00m\u001b[33m\"\u001b[39m\n\u001b[32m    215\u001b[39m     ) \u001b[38;5;28;01mfrom\u001b[39;00m\u001b[38;5;250m \u001b[39m\u001b[34;01me\u001b[39;00m\n\u001b[32m    217\u001b[39m sys.audit(\u001b[33m\"\u001b[39m\u001b[33mhttp.client.connect\u001b[39m\u001b[33m\"\u001b[39m, \u001b[38;5;28mself\u001b[39m, \u001b[38;5;28mself\u001b[39m.host, \u001b[38;5;28mself\u001b[39m.port)\n",
      "\u001b[31mNewConnectionError\u001b[39m: <urllib3.connection.HTTPConnection object at 0x7bc00c08f4a0>: Failed to establish a new connection: [Errno 111] Connection refused",
      "\nThe above exception was the direct cause of the following exception:\n",
      "\u001b[31mMaxRetryError\u001b[39m                             Traceback (most recent call last)",
      "\u001b[36mFile \u001b[39m\u001b[32m~/.local/lib/python3.12/site-packages/requests/adapters.py:667\u001b[39m, in \u001b[36mHTTPAdapter.send\u001b[39m\u001b[34m(self, request, stream, timeout, verify, cert, proxies)\u001b[39m\n\u001b[32m    666\u001b[39m \u001b[38;5;28;01mtry\u001b[39;00m:\n\u001b[32m--> \u001b[39m\u001b[32m667\u001b[39m     resp = \u001b[43mconn\u001b[49m\u001b[43m.\u001b[49m\u001b[43murlopen\u001b[49m\u001b[43m(\u001b[49m\n\u001b[32m    668\u001b[39m \u001b[43m        \u001b[49m\u001b[43mmethod\u001b[49m\u001b[43m=\u001b[49m\u001b[43mrequest\u001b[49m\u001b[43m.\u001b[49m\u001b[43mmethod\u001b[49m\u001b[43m,\u001b[49m\n\u001b[32m    669\u001b[39m \u001b[43m        \u001b[49m\u001b[43murl\u001b[49m\u001b[43m=\u001b[49m\u001b[43murl\u001b[49m\u001b[43m,\u001b[49m\n\u001b[32m    670\u001b[39m \u001b[43m        \u001b[49m\u001b[43mbody\u001b[49m\u001b[43m=\u001b[49m\u001b[43mrequest\u001b[49m\u001b[43m.\u001b[49m\u001b[43mbody\u001b[49m\u001b[43m,\u001b[49m\n\u001b[32m    671\u001b[39m \u001b[43m        \u001b[49m\u001b[43mheaders\u001b[49m\u001b[43m=\u001b[49m\u001b[43mrequest\u001b[49m\u001b[43m.\u001b[49m\u001b[43mheaders\u001b[49m\u001b[43m,\u001b[49m\n\u001b[32m    672\u001b[39m \u001b[43m        \u001b[49m\u001b[43mredirect\u001b[49m\u001b[43m=\u001b[49m\u001b[38;5;28;43;01mFalse\u001b[39;49;00m\u001b[43m,\u001b[49m\n\u001b[32m    673\u001b[39m \u001b[43m        \u001b[49m\u001b[43massert_same_host\u001b[49m\u001b[43m=\u001b[49m\u001b[38;5;28;43;01mFalse\u001b[39;49;00m\u001b[43m,\u001b[49m\n\u001b[32m    674\u001b[39m \u001b[43m        \u001b[49m\u001b[43mpreload_content\u001b[49m\u001b[43m=\u001b[49m\u001b[38;5;28;43;01mFalse\u001b[39;49;00m\u001b[43m,\u001b[49m\n\u001b[32m    675\u001b[39m \u001b[43m        \u001b[49m\u001b[43mdecode_content\u001b[49m\u001b[43m=\u001b[49m\u001b[38;5;28;43;01mFalse\u001b[39;49;00m\u001b[43m,\u001b[49m\n\u001b[32m    676\u001b[39m \u001b[43m        \u001b[49m\u001b[43mretries\u001b[49m\u001b[43m=\u001b[49m\u001b[38;5;28;43mself\u001b[39;49m\u001b[43m.\u001b[49m\u001b[43mmax_retries\u001b[49m\u001b[43m,\u001b[49m\n\u001b[32m    677\u001b[39m \u001b[43m        \u001b[49m\u001b[43mtimeout\u001b[49m\u001b[43m=\u001b[49m\u001b[43mtimeout\u001b[49m\u001b[43m,\u001b[49m\n\u001b[32m    678\u001b[39m \u001b[43m        \u001b[49m\u001b[43mchunked\u001b[49m\u001b[43m=\u001b[49m\u001b[43mchunked\u001b[49m\u001b[43m,\u001b[49m\n\u001b[32m    679\u001b[39m \u001b[43m    \u001b[49m\u001b[43m)\u001b[49m\n\u001b[32m    681\u001b[39m \u001b[38;5;28;01mexcept\u001b[39;00m (ProtocolError, \u001b[38;5;167;01mOSError\u001b[39;00m) \u001b[38;5;28;01mas\u001b[39;00m err:\n",
      "\u001b[36mFile \u001b[39m\u001b[32m~/.local/lib/python3.12/site-packages/urllib3/connectionpool.py:841\u001b[39m, in \u001b[36mHTTPConnectionPool.urlopen\u001b[39m\u001b[34m(self, method, url, body, headers, retries, redirect, assert_same_host, timeout, pool_timeout, release_conn, chunked, body_pos, preload_content, decode_content, **response_kw)\u001b[39m\n\u001b[32m    839\u001b[39m     new_e = ProtocolError(\u001b[33m\"\u001b[39m\u001b[33mConnection aborted.\u001b[39m\u001b[33m\"\u001b[39m, new_e)\n\u001b[32m--> \u001b[39m\u001b[32m841\u001b[39m retries = \u001b[43mretries\u001b[49m\u001b[43m.\u001b[49m\u001b[43mincrement\u001b[49m\u001b[43m(\u001b[49m\n\u001b[32m    842\u001b[39m \u001b[43m    \u001b[49m\u001b[43mmethod\u001b[49m\u001b[43m,\u001b[49m\u001b[43m \u001b[49m\u001b[43murl\u001b[49m\u001b[43m,\u001b[49m\u001b[43m \u001b[49m\u001b[43merror\u001b[49m\u001b[43m=\u001b[49m\u001b[43mnew_e\u001b[49m\u001b[43m,\u001b[49m\u001b[43m \u001b[49m\u001b[43m_pool\u001b[49m\u001b[43m=\u001b[49m\u001b[38;5;28;43mself\u001b[39;49m\u001b[43m,\u001b[49m\u001b[43m \u001b[49m\u001b[43m_stacktrace\u001b[49m\u001b[43m=\u001b[49m\u001b[43msys\u001b[49m\u001b[43m.\u001b[49m\u001b[43mexc_info\u001b[49m\u001b[43m(\u001b[49m\u001b[43m)\u001b[49m\u001b[43m[\u001b[49m\u001b[32;43m2\u001b[39;49m\u001b[43m]\u001b[49m\n\u001b[32m    843\u001b[39m \u001b[43m\u001b[49m\u001b[43m)\u001b[49m\n\u001b[32m    844\u001b[39m retries.sleep()\n",
      "\u001b[36mFile \u001b[39m\u001b[32m~/.local/lib/python3.12/site-packages/urllib3/util/retry.py:519\u001b[39m, in \u001b[36mRetry.increment\u001b[39m\u001b[34m(self, method, url, response, error, _pool, _stacktrace)\u001b[39m\n\u001b[32m    518\u001b[39m     reason = error \u001b[38;5;129;01mor\u001b[39;00m ResponseError(cause)\n\u001b[32m--> \u001b[39m\u001b[32m519\u001b[39m     \u001b[38;5;28;01mraise\u001b[39;00m MaxRetryError(_pool, url, reason) \u001b[38;5;28;01mfrom\u001b[39;00m\u001b[38;5;250m \u001b[39m\u001b[34;01mreason\u001b[39;00m  \u001b[38;5;66;03m# type: ignore[arg-type]\u001b[39;00m\n\u001b[32m    521\u001b[39m log.debug(\u001b[33m\"\u001b[39m\u001b[33mIncremented Retry for (url=\u001b[39m\u001b[33m'\u001b[39m\u001b[38;5;132;01m%s\u001b[39;00m\u001b[33m'\u001b[39m\u001b[33m): \u001b[39m\u001b[38;5;132;01m%r\u001b[39;00m\u001b[33m\"\u001b[39m, url, new_retry)\n",
      "\u001b[31mMaxRetryError\u001b[39m: HTTPConnectionPool(host='localhost', port=9696): Max retries exceeded with url: /predict (Caused by NewConnectionError('<urllib3.connection.HTTPConnection object at 0x7bc00c08f4a0>: Failed to establish a new connection: [Errno 111] Connection refused'))",
      "\nDuring handling of the above exception, another exception occurred:\n",
      "\u001b[31mConnectionError\u001b[39m                           Traceback (most recent call last)",
      "\u001b[36mCell\u001b[39m\u001b[36m \u001b[39m\u001b[32mIn[29]\u001b[39m\u001b[32m, line 1\u001b[39m\n\u001b[32m----> \u001b[39m\u001b[32m1\u001b[39m response = \u001b[43mrequests\u001b[49m\u001b[43m.\u001b[49m\u001b[43mpost\u001b[49m\u001b[43m(\u001b[49m\u001b[43murl\u001b[49m\u001b[43m,\u001b[49m\u001b[43m \u001b[49m\u001b[43mjson\u001b[49m\u001b[43m=\u001b[49m\u001b[43mcustomer\u001b[49m\u001b[43m)\u001b[49m \u001b[38;5;66;03m## post the customer information in json format\u001b[39;00m\n",
      "\u001b[36mFile \u001b[39m\u001b[32m~/.local/lib/python3.12/site-packages/requests/api.py:115\u001b[39m, in \u001b[36mpost\u001b[39m\u001b[34m(url, data, json, **kwargs)\u001b[39m\n\u001b[32m    103\u001b[39m \u001b[38;5;28;01mdef\u001b[39;00m\u001b[38;5;250m \u001b[39m\u001b[34mpost\u001b[39m(url, data=\u001b[38;5;28;01mNone\u001b[39;00m, json=\u001b[38;5;28;01mNone\u001b[39;00m, **kwargs):\n\u001b[32m    104\u001b[39m \u001b[38;5;250m    \u001b[39m\u001b[33mr\u001b[39m\u001b[33;03m\"\"\"Sends a POST request.\u001b[39;00m\n\u001b[32m    105\u001b[39m \n\u001b[32m    106\u001b[39m \u001b[33;03m    :param url: URL for the new :class:`Request` object.\u001b[39;00m\n\u001b[32m   (...)\u001b[39m\u001b[32m    112\u001b[39m \u001b[33;03m    :rtype: requests.Response\u001b[39;00m\n\u001b[32m    113\u001b[39m \u001b[33;03m    \"\"\"\u001b[39;00m\n\u001b[32m--> \u001b[39m\u001b[32m115\u001b[39m     \u001b[38;5;28;01mreturn\u001b[39;00m \u001b[43mrequest\u001b[49m\u001b[43m(\u001b[49m\u001b[33;43m\"\u001b[39;49m\u001b[33;43mpost\u001b[39;49m\u001b[33;43m\"\u001b[39;49m\u001b[43m,\u001b[49m\u001b[43m \u001b[49m\u001b[43murl\u001b[49m\u001b[43m,\u001b[49m\u001b[43m \u001b[49m\u001b[43mdata\u001b[49m\u001b[43m=\u001b[49m\u001b[43mdata\u001b[49m\u001b[43m,\u001b[49m\u001b[43m \u001b[49m\u001b[43mjson\u001b[49m\u001b[43m=\u001b[49m\u001b[43mjson\u001b[49m\u001b[43m,\u001b[49m\u001b[43m \u001b[49m\u001b[43m*\u001b[49m\u001b[43m*\u001b[49m\u001b[43mkwargs\u001b[49m\u001b[43m)\u001b[49m\n",
      "\u001b[36mFile \u001b[39m\u001b[32m~/.local/lib/python3.12/site-packages/requests/api.py:59\u001b[39m, in \u001b[36mrequest\u001b[39m\u001b[34m(method, url, **kwargs)\u001b[39m\n\u001b[32m     55\u001b[39m \u001b[38;5;66;03m# By using the 'with' statement we are sure the session is closed, thus we\u001b[39;00m\n\u001b[32m     56\u001b[39m \u001b[38;5;66;03m# avoid leaving sockets open which can trigger a ResourceWarning in some\u001b[39;00m\n\u001b[32m     57\u001b[39m \u001b[38;5;66;03m# cases, and look like a memory leak in others.\u001b[39;00m\n\u001b[32m     58\u001b[39m \u001b[38;5;28;01mwith\u001b[39;00m sessions.Session() \u001b[38;5;28;01mas\u001b[39;00m session:\n\u001b[32m---> \u001b[39m\u001b[32m59\u001b[39m     \u001b[38;5;28;01mreturn\u001b[39;00m \u001b[43msession\u001b[49m\u001b[43m.\u001b[49m\u001b[43mrequest\u001b[49m\u001b[43m(\u001b[49m\u001b[43mmethod\u001b[49m\u001b[43m=\u001b[49m\u001b[43mmethod\u001b[49m\u001b[43m,\u001b[49m\u001b[43m \u001b[49m\u001b[43murl\u001b[49m\u001b[43m=\u001b[49m\u001b[43murl\u001b[49m\u001b[43m,\u001b[49m\u001b[43m \u001b[49m\u001b[43m*\u001b[49m\u001b[43m*\u001b[49m\u001b[43mkwargs\u001b[49m\u001b[43m)\u001b[49m\n",
      "\u001b[36mFile \u001b[39m\u001b[32m~/.local/lib/python3.12/site-packages/requests/sessions.py:589\u001b[39m, in \u001b[36mSession.request\u001b[39m\u001b[34m(self, method, url, params, data, headers, cookies, files, auth, timeout, allow_redirects, proxies, hooks, stream, verify, cert, json)\u001b[39m\n\u001b[32m    584\u001b[39m send_kwargs = {\n\u001b[32m    585\u001b[39m     \u001b[33m\"\u001b[39m\u001b[33mtimeout\u001b[39m\u001b[33m\"\u001b[39m: timeout,\n\u001b[32m    586\u001b[39m     \u001b[33m\"\u001b[39m\u001b[33mallow_redirects\u001b[39m\u001b[33m\"\u001b[39m: allow_redirects,\n\u001b[32m    587\u001b[39m }\n\u001b[32m    588\u001b[39m send_kwargs.update(settings)\n\u001b[32m--> \u001b[39m\u001b[32m589\u001b[39m resp = \u001b[38;5;28;43mself\u001b[39;49m\u001b[43m.\u001b[49m\u001b[43msend\u001b[49m\u001b[43m(\u001b[49m\u001b[43mprep\u001b[49m\u001b[43m,\u001b[49m\u001b[43m \u001b[49m\u001b[43m*\u001b[49m\u001b[43m*\u001b[49m\u001b[43msend_kwargs\u001b[49m\u001b[43m)\u001b[49m\n\u001b[32m    591\u001b[39m \u001b[38;5;28;01mreturn\u001b[39;00m resp\n",
      "\u001b[36mFile \u001b[39m\u001b[32m~/.local/lib/python3.12/site-packages/requests/sessions.py:703\u001b[39m, in \u001b[36mSession.send\u001b[39m\u001b[34m(self, request, **kwargs)\u001b[39m\n\u001b[32m    700\u001b[39m start = preferred_clock()\n\u001b[32m    702\u001b[39m \u001b[38;5;66;03m# Send the request\u001b[39;00m\n\u001b[32m--> \u001b[39m\u001b[32m703\u001b[39m r = \u001b[43madapter\u001b[49m\u001b[43m.\u001b[49m\u001b[43msend\u001b[49m\u001b[43m(\u001b[49m\u001b[43mrequest\u001b[49m\u001b[43m,\u001b[49m\u001b[43m \u001b[49m\u001b[43m*\u001b[49m\u001b[43m*\u001b[49m\u001b[43mkwargs\u001b[49m\u001b[43m)\u001b[49m\n\u001b[32m    705\u001b[39m \u001b[38;5;66;03m# Total elapsed time of the request (approximately)\u001b[39;00m\n\u001b[32m    706\u001b[39m elapsed = preferred_clock() - start\n",
      "\u001b[36mFile \u001b[39m\u001b[32m~/.local/lib/python3.12/site-packages/requests/adapters.py:700\u001b[39m, in \u001b[36mHTTPAdapter.send\u001b[39m\u001b[34m(self, request, stream, timeout, verify, cert, proxies)\u001b[39m\n\u001b[32m    696\u001b[39m     \u001b[38;5;28;01mif\u001b[39;00m \u001b[38;5;28misinstance\u001b[39m(e.reason, _SSLError):\n\u001b[32m    697\u001b[39m         \u001b[38;5;66;03m# This branch is for urllib3 v1.22 and later.\u001b[39;00m\n\u001b[32m    698\u001b[39m         \u001b[38;5;28;01mraise\u001b[39;00m SSLError(e, request=request)\n\u001b[32m--> \u001b[39m\u001b[32m700\u001b[39m     \u001b[38;5;28;01mraise\u001b[39;00m \u001b[38;5;167;01mConnectionError\u001b[39;00m(e, request=request)\n\u001b[32m    702\u001b[39m \u001b[38;5;28;01mexcept\u001b[39;00m ClosedPoolError \u001b[38;5;28;01mas\u001b[39;00m e:\n\u001b[32m    703\u001b[39m     \u001b[38;5;28;01mraise\u001b[39;00m \u001b[38;5;167;01mConnectionError\u001b[39;00m(e, request=request)\n",
      "\u001b[31mConnectionError\u001b[39m: HTTPConnectionPool(host='localhost', port=9696): Max retries exceeded with url: /predict (Caused by NewConnectionError('<urllib3.connection.HTTPConnection object at 0x7bc00c08f4a0>: Failed to establish a new connection: [Errno 111] Connection refused'))"
     ]
    }
   ],
   "source": [
    "response = requests.post(url, json=customer) ## post the customer information in json format"
   ]
  },
  {
   "cell_type": "code",
   "execution_count": null,
   "id": "4b914c9e-1e20-4303-b475-6bc5dda81f37",
   "metadata": {},
   "outputs": [],
   "source": [
    "result = response.json() ## get the server response"
   ]
  },
  {
   "cell_type": "code",
   "execution_count": 30,
   "id": "2ad7636e-e8e6-4365-a5b1-3c1a22ebf709",
   "metadata": {},
   "outputs": [
    {
     "name": "stdout",
     "output_type": "stream",
     "text": [
      "{'churn': True, 'churn_probability': 0.6433010959417496}\n"
     ]
    }
   ],
   "source": [
    "print(result)"
   ]
  },
  {
   "cell_type": "code",
   "execution_count": null,
   "id": "5d96bfe5-6f8b-49b5-98d6-2726dcbb1f69",
   "metadata": {},
   "outputs": [],
   "source": []
  },
  {
   "cell_type": "code",
   "execution_count": null,
   "id": "cef44382-b5dc-4830-a51f-7cab0ffb18b9",
   "metadata": {},
   "outputs": [],
   "source": []
  }
 ],
 "metadata": {
  "kernelspec": {
   "display_name": "Python 3 (ipykernel)",
   "language": "python",
   "name": "python3"
  },
  "language_info": {
   "codemirror_mode": {
    "name": "ipython",
    "version": 3
   },
   "file_extension": ".py",
   "mimetype": "text/x-python",
   "name": "python",
   "nbconvert_exporter": "python",
   "pygments_lexer": "ipython3",
   "version": "3.12.3"
  }
 },
 "nbformat": 4,
 "nbformat_minor": 5
}
